Workbook

Sheet _
A1: Folio Trámite | B1: Cuenta Individual | C1: Tipo de Trámite | D1: Estatus de trámites | E1: Fecha Estatus | F1: Monto Total | G1: Monto Total de Acciones | H1: NSS | I1: CURP | J1: Proceso | K1: Tipo de Solicitante | L1: CURP Solicitante | M1: Sucursal | N1: Fecha de Captura | O1: Clasificación del Rechazo | P1: Motivos de Rechazo | Q1: Fecha Envio a Beneficios | R1: Fecha Liquidado | S1: Contador de Reactivación | T1: Cliente Notificado | U1: Sello de Verificación | V1: Identificación Trámite | W1: Folio Trámite_2 | X1: Folio_Nuevo_Cognos | Y1: BO_IC_IMPORTE | Z1: BO_IC_IMPORTE_VS_MONTO_TOTAL | AA1: BO_IC_MENSUALIDAD | AB1: BO_IC_P1_SUMA_SUBSECUENTE | AC1: BO_IC_P1_IMPORTE_TOTAL | AD1: FECHA_MAT | AE1: SALARIO MINIMO | AF1: UMA | AG1: VALIDACION_30*SM | AH1: VALIDACION_30*UMA | AI1: RESULTADO_VAL1 | AJ1: FECHA_SOLICITUD | AK1: SALARIO A | AL1: SALARIO B | AM1: VALIDACION_30*SALA | AN1: VALIDACION_90*SALB | AO1: RESULTADO_VAL2 | AP1: SCS_RCV_ACCIONES | AQ1: SCS_CODIGO_SIEFORE | AR1: SCS_VALOR_ACCION | AS1: SCS_RCV_PESOS | AT1: 11.5%_RCV | AU1: RESULTADO_VAL3 | AV1: BO_IMPORTE_PRIMER_IC_PS | AW1: RESULTADO_VAL_SUBSECUENTE | AX1: SUMA_PAGOS_EN_PROCESO | AY1: RESULTADO_VAL_SUMA | AZ1: VALIDACION_PAGO_1 | BA1: RESULTADO_VAL_PAGO_1 | BB1: IMPORTE_A_LIQUIDAR | BC1: ESTATUS | BD1: COMENTARIO | BE1: ESTADO_TRANSACCION | BF1: BOT_ESTADO
A2: 8000251483 | B2: 3300375746 | C2: RETIRO POR DESEMPLEO IMSS | D2: CON IMAGENES COMPLETAS | E2: 44120.591 | F2: 5926.2 | G2: 0 | H2: 10149363516 | I2: RAPJ930124HCHMRS02 | J2: RETIRO PARCIAL IMSS | K2: Titular/Trabajador | L2: RAPJ930124HCHMRS02 | M2: CD. JUAREZ | N2: 20201016 14:03:35 | T2: 1 | U2: 72854047234662 | W2: 202010161356104077 | Y2: 5926.2 | Z2: =IF(Y2=F2,"OK","Error 1") -> OK | AA2: Pago único | AC2: =IF(AA2="Pago 1",AB2+Y2,"0") -> 0 | AD2: 44117 | AE2: =IF(V2="SUBSECUENTE","No aplica",VLOOKUP(YEAR(AD2),'SALARIO MINIMO'!A1:B100,2,FALSE)) -> 123.22 | AF2: =IF(V2="SUBSECUENTE","No aplica",IF(YEAR(AD2)=2016,VLOOKUP(YEAR(AD2),UMA!A1:B100,2,FALSE),IF(MONTH(AD2)=1,VLOOKUP((YEAR(AD2))-1,UMA!A1:B100,2,FALSE),VLOOKUP(YEAR(AD2),UMA!A1:B100,2,FALSE)))) -> 86.88 | AG2: =IF(V2="SUBSECUENTE","No aplica",IFERROR(IF(SEARCH("desempleo",C2),AE2*30*10),AE2*30)) -> 36966 | AH2: =IF(V2="SUBSECUENTE","No aplica",IFERROR(IF(SEARCH("desempleo",C2),AF2*30*10),AF2*30)) -> 26064 | AI2: =IF(V2="SUBSECUENTE","No aplica",IF(AA2="Pago único",IF(AG2=Y2,"OK_SM",IF(AH2=Y2,"OK_UMA","Error Validacion 1")),IF(AG2=AC2,"OK_SM",IF(AH2=AC2,"OK_UMA","Error Validacion 1")))) -> Error Validacion 1 | AJ2: =N2 -> 20201016 14:03:35 | AK2: 197.54 | AL2: 120.89 | AM2: =IF(C2="RETIRO POR MATRIMONIO IMSS", 0,AK2*30) -> 5926.2 | AN2: =IF(C2="RETIRO POR MATRIMONIO IMSS", 0,AL2*90) -> 10880.1 | AO2: =IF(V2="SUBSECUENTE","No aplica",IF(AA2="Pago único",IF(AM2=Y2,"OK_SALA",IF(AN2=Y2,"OK_SALB","Revisar_11.5%")),IF(AM2=AC2,"OK_SALA",IF(AN2=AC2,"OK_SALB","Revisar_11.5%")))) -> OK_SALA | AP2: 2097.9583 | AQ2: PROF-90 | AR2: 13.148607 | AS2: =AP2*AR2 -> 27585.229 | AT2: =IF(V2="SUBSECUENTE","No aplica",IF(AO2="OK_SALA","SAL_A",IF(AO2="OK_SALB","SAL_B",IF(AO2="Revisar_11.5%",AS2*0.115,"Error Validación 2")))) -> SAL_A | AU2: =IF(V2="SUBSECUENTE","No aplica",IF(AA2="Pago único",IF(AT2<>"SAL_A",IF(ABS(AT2-Y2)<0.02,"OK_11.5%",IF(ABS(AS2-Y2)<0.02,"OK_RCV","Error Validación 4")),"SAL_A"),IF(AT2<>"SAL_A",IF(ABS(AT2-AC2)<0.02,"OK_11.5%",IF(ABS(AS2-AC2)<0.02,"OK_RCV","Error Validación 4")),"SAL_A"))) -> SAL_A | AW2: =IF(V2="SUBSECUENTE",IF(AV2=Y2,"OK_IC","Revisar Pendientes"),"") | AY2: =IF(V2="SUBSECUENTES","No aplica",IF(AX2=Y2,"OK_SUMA","Diferencia pagos en curso")) -> Diferencia pagos en curso | AZ2: =IF(AA2="Pago 1",IF(AI2="OK_SM",AG2,IF(AI2="OK_UMA",AH2,IF(AO2="OK_SALA",AM2,IF(AO2="OK_SALB",AN2,IF(AU2="OK_11.5%",AT2,IF(AU2="OK_RCV",AS2,"Error en validación")))))),"No aplica") -> No aplica | BA2: =IF(ISNUMBER(AZ2),"OK_cálculo pago 1",AZ2) -> No aplica | BB2: =IF(AW2="OK_IC",AV2,IF(AY2="OK_SUMA",AX2,IF(AI2="OK_SM",AG2,IF(AI2="OK_UMA",AH2,IF(AO2="OK_SALA",AM2,IF(AO2="OK_SALB",AN2,IF(AU2="OK_11.5%",AT2,IF(AU2="OK_RCV",AS2,"Error en validación")))))))) -> 5926.2 | BC2: =IF(Z2="Error 1","No cuadran el Instructivo de Cobro y el monto de Cognos",IF(AND(AW2="Revisar Pendientes",AY2<>"OK_SUMA"),"Diferencia entre instructivo de cobro actual y de primer pago",IF(AI2<>"Error Validacion 1","Validación correcta",IF(OR(AO2="OK_SALA",AO2="OK_SALB"),"Validación correcta", IF(AU2="Error Validación 4", IF(AA2="Pago único","No cuadra el cálculo realizado contra Instructivo y Cognos","No cuadra cálculo realizado contra Instructivo"), "Validación correcta"))))) -> Validación correcta | BD2: =IF(BC2="Validación correcta","Ningún comentario",IF(BC2="No cuadran el Instructivo de Cobro y el monto de Cognos","Inconsistencia en los datos de origen","Inconsistencia entre datos de origen y cálculo")) -> Ningún comentario | BE2: Actual | BF2: Procesado
A3: 8000250790 | B3: 3200494338 | C3: RETIRO DE AYUDA PARA GASTOS DE MATRIMONIO IMSS | D3: ACEPTADO MC | E3: 44120.4 | F3: 2606.4 | G3: 0 | H3: 16099147890 | I3: OEBJ910507HMCRTV06 | J3: RETIRO PARCIAL IMSS | K3: Titular/Trabajador | L3: OEBJ910507HMCRTV06 | M3: TOLUCA | N3: 20201016 09:31:51 | T3: 1 | U3: 39839285121581 | W3: 202010160923090008 | Y3: 2606.4 | Z3: =IF(Y3=F3,"OK","Error 1") -> OK | AA3: Pago único | AC3: =IF(AA3="Pago 1",AB3+Y3,"0") -> 0 | AD3: 44092 | AE3: =IF(V3="SUBSECUENTE","No aplica",VLOOKUP(YEAR(AD3),'SALARIO MINIMO'!A1:B100,2,FALSE)) -> 123.22 | AF3: =IF(V3="SUBSECUENTE","No aplica",IF(YEAR(AD3)=2016,VLOOKUP(YEAR(AD3),UMA!A1:B100,2,FALSE),IF(MONTH(AD3)=1,VLOOKUP((YEAR(AD3))-1,UMA!A1:B100,2,FALSE),VLOOKUP(YEAR(AD3),UMA!A1:B100,2,FALSE)))) -> 86.88 | AG3: =IF(V3="SUBSECUENTE","No aplica",IFERROR(IF(SEARCH("desempleo",C3),AE3*30*10),AE3*30)) -> 3696.6 | AH3: =IF(V3="SUBSECUENTE","No aplica",IFERROR(IF(SEARCH("desempleo",C3),AF3*30*10),AF3*30)) -> 2606.4 | AI3: =IF(V3="SUBSECUENTE","No aplica",IF(AA3="Pago único",IF(AG3=Y3,"OK_SM",IF(AH3=Y3,"OK_UMA","Error Validacion 1")),IF(AG3=AC3,"OK_SM",IF(AH3=AC3,"OK_UMA","Error Validacion 1")))) -> OK_UMA | AJ3: =N3 -> 20201016 09:31:51 | AK3: 2606.4 | AL3: 0 | AM3: =IF(C3="RETIRO POR MATRIMONIO IMSS", 0,AK3*30) -> 78192 | AN3: =IF(C3="RETIRO POR MATRIMONIO IMSS", 0,AL3*90) -> 0 | AO3: =IF(V3="SUBSECUENTE","No aplica",IF(AA3="Pago único",IF(AM3=Y3,"OK_SALA",IF(AN3=Y3,"OK_SALB","Revisar_11.5%")),IF(AM3=AC3,"OK_SALA",IF(AN3=AC3,"OK_SALB","Revisar_11.5%")))) -> Revisar_11.5% | AP3: 3389.4653 | AQ3: PROF-90 | AR3: 13.148607 | AS3: =AP3*AR3 -> 44566.747 | AT3: =IF(V3="SUBSECUENTE","No aplica",IF(AO3="OK_SALA","SAL_A",IF(AO3="OK_SALB","SAL_B",IF(AO3="Revisar_11.5%",AS3*0.115,"Error Validación 2")))) -> 5125.1759 | AU3: =IF(V3="SUBSECUENTE","No aplica",IF(AA3="Pago único",IF(AT3<>"SAL_A",IF(ABS(AT3-Y3)<0.02,"OK_11.5%",IF(ABS(AS3-Y3)<0.02,"OK_RCV","Error Validación 4")),"SAL_A"),IF(AT3<>"SAL_A",IF(ABS(AT3-AC3)<0.02,"OK_11.5%",IF(ABS(AS3-AC3)<0.02,"OK_RCV","Error Validación 4")),"SAL_A"))) -> Error Validación 4 | AW3: =IF(V3="SUBSECUENTE",IF(AV3=Y3,"OK_IC","Revisar Pendientes"),"") | AY3: =IF(V3="SUBSECUENTES","No aplica",IF(AX3=Y3,"OK_SUMA","Diferencia pagos en curso")) -> Diferencia pagos en curso | AZ3: =IF(AA3="Pago 1",IF(AI3="OK_SM",AG3,IF(AI3="OK_UMA",AH3,IF(AO3="OK_SALA",AM3,IF(AO3="OK_SALB",AN3,IF(AU3="OK_11.5%",AT3,IF(AU3="OK_RCV",AS3,"Error en validación")))))),"No aplica") -> No aplica | BA3: =IF(ISNUMBER(AZ3),"OK_cálculo pago 1",AZ3) -> No aplica | BB3: =IF(AW3="OK_IC",AV3,IF(AY3="OK_SUMA",AX3,IF(AI3="OK_SM",AG3,IF(AI3="OK_UMA",AH3,IF(AO3="OK_SALA",AM3,IF(AO3="OK_SALB",AN3,IF(AU3="OK_11.5%",AT3,IF(AU3="OK_RCV",AS3,"Error en validación")))))))) -> 2606.4 | BC3: =IF(Z3="Error 1","No cuadran el Instructivo de Cobro y el monto de Cognos",IF(AND(AW3="Revisar Pendientes",AY3<>"OK_SUMA"),"Diferencia entre instructivo de cobro actual y de primer pago",IF(AI3<>"Error Validacion 1","Validación correcta",IF(OR(AO3="OK_SALA",AO3="OK_SALB"),"Validación correcta", IF(AU3="Error Validación 4", IF(AA3="Pago único","No cuadra el cálculo realizado contra Instructivo y Cognos","No cuadra cálculo realizado contra Instructivo"), "Validación correcta"))))) -> Validación correcta | BD3: =IF(BC3="Validación correcta","Ningún comentario",IF(BC3="No cuadran el Instructivo de Cobro y el monto de Cognos","Inconsistencia en los datos de origen","Inconsistencia entre datos de origen y cálculo")) -> Ningún comentario | BE3: Actual | BF3: Procesado
A4: 8000251189 | B4: 3300416393 | C4: RETIRO DE AYUDA PARA GASTOS DE MATRIMONIO IMSS | D4: ACEPTADO MC | E4: 44120.545 | F4: 2534.7 | G4: 0 | H4: 41119028144 | I4: RUED900721MSPZSN08 | J4: RETIRO PARCIAL IMSS | K4: Titular/Trabajador | L4: RUED900721MSPZSN08 | M4: SAN LUIS POTOSI | N4: 20201016 12:08:15 | T4: 1 | U4: 43044782931369 | W4: 202010161204490030 | Y4: 2534.7 | Z4: =IF(Y4=F4,"OK","Error 1") -> OK | AA4: Pago único | AC4: =IF(AA4="Pago 1",AB4+Y4,"0") -> 0 | AD4: 43680 | AE4: =IF(V4="SUBSECUENTE","No aplica",VLOOKUP(YEAR(AD4),'SALARIO MINIMO'!A1:B100,2,FALSE)) -> 102.68 | AF4: =IF(V4="SUBSECUENTE","No aplica",IF(YEAR(AD4)=2016,VLOOKUP(YEAR(AD4),UMA!A1:B100,2,FALSE),IF(MONTH(AD4)=1,VLOOKUP((YEAR(AD4))-1,UMA!A1:B100,2,FALSE),VLOOKUP(YEAR(AD4),UMA!A1:B100,2,FALSE)))) -> 84.49 | AG4: =IF(V4="SUBSECUENTE","No aplica",IFERROR(IF(SEARCH("desempleo",C4),AE4*30*10),AE4*30)) -> 3080.4 | AH4: =IF(V4="SUBSECUENTE","No aplica",IFERROR(IF(SEARCH("desempleo",C4),AF4*30*10),AF4*30)) -> 2534.7 | AI4: =IF(V4="SUBSECUENTE","No aplica",IF(AA4="Pago único",IF(AG4=Y4,"OK_SM",IF(AH4=Y4,"OK_UMA","Error Validacion 1")),IF(AG4=AC4,"OK_SM",IF(AH4=AC4,"OK_UMA","Error Validacion 1")))) -> OK_UMA | AJ4: =N4 -> 20201016 12:08:15 | AK4: 2534.7 | AL4: 0 | AM4: =IF(C4="RETIRO POR MATRIMONIO IMSS", 0,AK4*30) -> 76041 | AN4: =IF(C4="RETIRO POR MATRIMONIO IMSS", 0,AL4*90) -> 0 | AO4: =IF(V4="SUBSECUENTE","No aplica",IF(AA4="Pago único",IF(AM4=Y4,"OK_SALA",IF(AN4=Y4,"OK_SALB","Revisar_11.5%")),IF(AM4=AC4,"OK_SALA",IF(AN4=AC4,"OK_SALB","Revisar_11.5%")))) -> Revisar_11.5% | AP4: 3157.9573 | AQ4: PROF-90 | AR4: 13.148607 | AS4: =AP4*AR4 -> 41522.74 | AT4: =IF(V4="SUBSECUENTE","No aplica",IF(AO4="OK_SALA","SAL_A",IF(AO4="OK_SALB","SAL_B",IF(AO4="Revisar_11.5%",AS4*0.115,"Error Validación 2")))) -> 4775.1151 | AU4: =IF(V4="SUBSECUENTE","No aplica",IF(AA4="Pago único",IF(AT4<>"SAL_A",IF(ABS(AT4-Y4)<0.02,"OK_11.5%",IF(ABS(AS4-Y4)<0.02,"OK_RCV","Error Validación 4")),"SAL_A"),IF(AT4<>"SAL_A",IF(ABS(AT4-AC4)<0.02,"OK_11.5%",IF(ABS(AS4-AC4)<0.02,"OK_RCV","Error Validación 4")),"SAL_A"))) -> Error Validación 4 | AW4: =IF(V4="SUBSECUENTE",IF(AV4=Y4,"OK_IC","Revisar Pendientes"),"") | AY4: =IF(V4="SUBSECUENTES","No aplica",IF(AX4=Y4,"OK_SUMA","Diferencia pagos en curso")) -> Diferencia pagos en curso | AZ4: =IF(AA4="Pago 1",IF(AI4="OK_SM",AG4,IF(AI4="OK_UMA",AH4,IF(AO4="OK_SALA",AM4,IF(AO4="OK_SALB",AN4,IF(AU4="OK_11.5%",AT4,IF(AU4="OK_RCV",AS4,"Error en validación")))))),"No aplica") -> No aplica | BA4: =IF(ISNUMBER(AZ4),"OK_cálculo pago 1",AZ4) -> No aplica | BB4: =IF(AW4="OK_IC",AV4,IF(AY4="OK_SUMA",AX4,IF(AI4="OK_SM",AG4,IF(AI4="OK_UMA",AH4,IF(AO4="OK_SALA",AM4,IF(AO4="OK_SALB",AN4,IF(AU4="OK_11.5%",AT4,IF(AU4="OK_RCV",AS4,"Error en validación")))))))) -> 2534.7 | BC4: =IF(Z4="Error 1","No cuadran el Instructivo de Cobro y el monto de Cognos",IF(AND(AW4="Revisar Pendientes",AY4<>"OK_SUMA"),"Diferencia entre instructivo de cobro actual y de primer pago",IF(AI4<>"Error Validacion 1","Validación correcta",IF(OR(AO4="OK_SALA",AO4="OK_SALB"),"Validación correcta", IF(AU4="Error Validación 4", IF(AA4="Pago único","No cuadra el cálculo realizado contra Instructivo y Cognos","No cuadra cálculo realizado contra Instructivo"), "Validación correcta"))))) -> Validación correcta | BD4: =IF(BC4="Validación correcta","Ningún comentario",IF(BC4="No cuadran el Instructivo de Cobro y el monto de Cognos","Inconsistencia en los datos de origen","Inconsistencia entre datos de origen y cálculo")) -> Ningún comentario | BE4: Actual | BF4: Procesado
A5: 8000251209 | B5: 3300345189 | C5: RETIRO DE AYUDA PARA GASTOS DE MATRIMONIO IMSS | D5: ACEPTADO MC | E5: 44120.547 | F5: 2606.4 | G5: 0 | H5: 56169634286 | I5: GOLS960723MGTDPR07 | J5: RETIRO PARCIAL IMSS | K5: Titular/Trabajador | L5: GOLS960723MGTDPR07 | M5: LEON | N5: 20201016 12:11:43 | T5: 1 | U5: 11473888228604 | W5: 202010161207320031 | Y5: 2606.4 | Z5: =IF(Y5=F5,"OK","Error 1") -> OK | AA5: Pago único | AC5: =IF(AA5="Pago 1",AB5+Y5,"0") -> 0 | AD5: 44099 | AE5: =IF(V5="SUBSECUENTE","No aplica",VLOOKUP(YEAR(AD5),'SALARIO MINIMO'!A1:B100,2,FALSE)) -> 123.22 | AF5: =IF(V5="SUBSECUENTE","No aplica",IF(YEAR(AD5)=2016,VLOOKUP(YEAR(AD5),UMA!A1:B100,2,FALSE),IF(MONTH(AD5)=1,VLOOKUP((YEAR(AD5))-1,UMA!A1:B100,2,FALSE),VLOOKUP(YEAR(AD5),UMA!A1:B100,2,FALSE)))) -> 86.88 | AG5: =IF(V5="SUBSECUENTE","No aplica",IFERROR(IF(SEARCH("desempleo",C5),AE5*30*10),AE5*30)) -> 3696.6 | AH5: =IF(V5="SUBSECUENTE","No aplica",IFERROR(IF(SEARCH("desempleo",C5),AF5*30*10),AF5*30)) -> 2606.4 | AI5: =IF(V5="SUBSECUENTE","No aplica",IF(AA5="Pago único",IF(AG5=Y5,"OK_SM",IF(AH5=Y5,"OK_UMA","Error Validacion 1")),IF(AG5=AC5,"OK_SM",IF(AH5=AC5,"OK_UMA","Error Validacion 1")))) -> OK_UMA | AJ5: =N5 -> 20201016 12:11:43 | AK5: 2606.4 | AL5: 0 | AM5: =IF(C5="RETIRO POR MATRIMONIO IMSS", 0,AK5*30) -> 78192 | AN5: =IF(C5="RETIRO POR MATRIMONIO IMSS", 0,AL5*90) -> 0 | AO5: =IF(V5="SUBSECUENTE","No aplica",IF(AA5="Pago único",IF(AM5=Y5,"OK_SALA",IF(AN5=Y5,"OK_SALB","Revisar_11.5%")),IF(AM5=AC5,"OK_SALA",IF(AN5=AC5,"OK_SALB","Revisar_11.5%")))) -> Revisar_11.5% | AP5: 1835.152 | AQ5: PROF-BI | AR5: 13.153222 | AS5: =AP5*AR5 -> 24138.161 | AT5: =IF(V5="SUBSECUENTE","No aplica",IF(AO5="OK_SALA","SAL_A",IF(AO5="OK_SALB","SAL_B",IF(AO5="Revisar_11.5%",AS5*0.115,"Error Validación 2")))) -> 2775.8885 | AU5: =IF(V5="SUBSECUENTE","No aplica",IF(AA5="Pago único",IF(AT5<>"SAL_A",IF(ABS(AT5-Y5)<0.02,"OK_11.5%",IF(ABS(AS5-Y5)<0.02,"OK_RCV","Error Validación 4")),"SAL_A"),IF(AT5<>"SAL_A",IF(ABS(AT5-AC5)<0.02,"OK_11.5%",IF(ABS(AS5-AC5)<0.02,"OK_RCV","Error Validación 4")),"SAL_A"))) -> Error Validación 4 | AW5: =IF(V5="SUBSECUENTE",IF(AV5=Y5,"OK_IC","Revisar Pendientes"),"") | AY5: =IF(V5="SUBSECUENTES","No aplica",IF(AX5=Y5,"OK_SUMA","Diferencia pagos en curso")) -> Diferencia pagos en curso | AZ5: =IF(AA5="Pago 1",IF(AI5="OK_SM",AG5,IF(AI5="OK_UMA",AH5,IF(AO5="OK_SALA",AM5,IF(AO5="OK_SALB",AN5,IF(AU5="OK_11.5%",AT5,IF(AU5="OK_RCV",AS5,"Error en validación")))))),"No aplica") -> No aplica | BA5: =IF(ISNUMBER(AZ5),"OK_cálculo pago 1",AZ5) -> No aplica | BB5: =IF(AW5="OK_IC",AV5,IF(AY5="OK_SUMA",AX5,IF(AI5="OK_SM",AG5,IF(AI5="OK_UMA",AH5,IF(AO5="OK_SALA",AM5,IF(AO5="OK_SALB",AN5,IF(AU5="OK_11.5%",AT5,IF(AU5="OK_RCV",AS5,"Error en validación")))))))) -> 2606.4 | BC5: =IF(Z5="Error 1","No cuadran el Instructivo de Cobro y el monto de Cognos",IF(AND(AW5="Revisar Pendientes",AY5<>"OK_SUMA"),"Diferencia entre instructivo de cobro actual y de primer pago",IF(AI5<>"Error Validacion 1","Validación correcta",IF(OR(AO5="OK_SALA",AO5="OK_SALB"),"Validación correcta", IF(AU5="Error Validación 4", IF(AA5="Pago único","No cuadra el cálculo realizado contra Instructivo y Cognos","No cuadra cálculo realizado contra Instructivo"), "Validación correcta"))))) -> Validación correcta | BD5: =IF(BC5="Validación correcta","Ningún comentario",IF(BC5="No cuadran el Instructivo de Cobro y el monto de Cognos","Inconsistencia en los datos de origen","Inconsistencia entre datos de origen y cálculo")) -> Ningún comentario | BE5: Actual | BF5: Procesado
A6: 8000251067 | B6: 2580010214 | C6: RETIRO DE AYUDA PARA GASTOS DE MATRIMONIO IMSS | D6: ACEPTADO MC | E6: 44120.565 | F6: 2606.4 | G6: 0 | H6: 47018541434 | I6: GOTJ850701HNLNLS00 | J6: RETIRO PARCIAL IMSS | K6: Titular/Trabajador | L6: GOTJ850701HNLNLS00 | M6: MONTERREY | N6: 20201016 11:08:20 | T6: 1 | U6: 50405095699647 | W6: 202010161103200023 | Y6: 2606.4 | Z6: =IF(Y6=F6,"OK","Error 1") -> OK | AA6: Pago único | AC6: =IF(AA6="Pago 1",AB6+Y6,"0") -> 0 | AD6: 44044 | AE6: =IF(V6="SUBSECUENTE","No aplica",VLOOKUP(YEAR(AD6),'SALARIO MINIMO'!A1:B100,2,FALSE)) -> 123.22 | AF6: =IF(V6="SUBSECUENTE","No aplica",IF(YEAR(AD6)=2016,VLOOKUP(YEAR(AD6),UMA!A1:B100,2,FALSE),IF(MONTH(AD6)=1,VLOOKUP((YEAR(AD6))-1,UMA!A1:B100,2,FALSE),VLOOKUP(YEAR(AD6),UMA!A1:B100,2,FALSE)))) -> 86.88 | AG6: =IF(V6="SUBSECUENTE","No aplica",IFERROR(IF(SEARCH("desempleo",C6),AE6*30*10),AE6*30)) -> 3696.6 | AH6: =IF(V6="SUBSECUENTE","No aplica",IFERROR(IF(SEARCH("desempleo",C6),AF6*30*10),AF6*30)) -> 2606.4 | AI6: =IF(V6="SUBSECUENTE","No aplica",IF(AA6="Pago único",IF(AG6=Y6,"OK_SM",IF(AH6=Y6,"OK_UMA","Error Validacion 1")),IF(AG6=AC6,"OK_SM",IF(AH6=AC6,"OK_UMA","Error Validacion 1")))) -> OK_UMA | AJ6: =N6 -> 20201016 11:08:20 | AK6: 2606.4 | AL6: 0 | AM6: =IF(C6="RETIRO POR MATRIMONIO IMSS", 0,AK6*30) -> 78192 | AN6: =IF(C6="RETIRO POR MATRIMONIO IMSS", 0,AL6*90) -> 0 | AO6: =IF(V6="SUBSECUENTE","No aplica",IF(AA6="Pago único",IF(AM6=Y6,"OK_SALA",IF(AN6=Y6,"OK_SALB","Revisar_11.5%")),IF(AM6=AC6,"OK_SALA",IF(AN6=AC6,"OK_SALB","Revisar_11.5%")))) -> Revisar_11.5% | AP6: 22534.103 | AQ6: PROF-85 | AR6: 13.238638 | AS6: =AP6*AR6 -> 298320.83 | AT6: =IF(V6="SUBSECUENTE","No aplica",IF(AO6="OK_SALA","SAL_A",IF(AO6="OK_SALB","SAL_B",IF(AO6="Revisar_11.5%",AS6*0.115,"Error Validación 2")))) -> 34306.895 | AU6: =IF(V6="SUBSECUENTE","No aplica",IF(AA6="Pago único",IF(AT6<>"SAL_A",IF(ABS(AT6-Y6)<0.02,"OK_11.5%",IF(ABS(AS6-Y6)<0.02,"OK_RCV","Error Validación 4")),"SAL_A"),IF(AT6<>"SAL_A",IF(ABS(AT6-AC6)<0.02,"OK_11.5%",IF(ABS(AS6-AC6)<0.02,"OK_RCV","Error Validación 4")),"SAL_A"))) -> Error Validación 4 | AW6: =IF(V6="SUBSECUENTE",IF(AV6=Y6,"OK_IC","Revisar Pendientes"),"") | AY6: =IF(V6="SUBSECUENTES","No aplica",IF(AX6=Y6,"OK_SUMA","Diferencia pagos en curso")) -> Diferencia pagos en curso | AZ6: =IF(AA6="Pago 1",IF(AI6="OK_SM",AG6,IF(AI6="OK_UMA",AH6,IF(AO6="OK_SALA",AM6,IF(AO6="OK_SALB",AN6,IF(AU6="OK_11.5%",AT6,IF(AU6="OK_RCV",AS6,"Error en validación")))))),"No aplica") -> No aplica | BA6: =IF(ISNUMBER(AZ6),"OK_cálculo pago 1",AZ6) -> No aplica | BB6: =IF(AW6="OK_IC",AV6,IF(AY6="OK_SUMA",AX6,IF(AI6="OK_SM",AG6,IF(AI6="OK_UMA",AH6,IF(AO6="OK_SALA",AM6,IF(AO6="OK_SALB",AN6,IF(AU6="OK_11.5%",AT6,IF(AU6="OK_RCV",AS6,"Error en validación")))))))) -> 2606.4 | BC6: =IF(Z6="Error 1","No cuadran el Instructivo de Cobro y el monto de Cognos",IF(AND(AW6="Revisar Pendientes",AY6<>"OK_SUMA"),"Diferencia entre instructivo de cobro actual y de primer pago",IF(AI6<>"Error Validacion 1","Validación correcta",IF(OR(AO6="OK_SALA",AO6="OK_SALB"),"Validación correcta", IF(AU6="Error Validación 4", IF(AA6="Pago único","No cuadra el cálculo realizado contra Instructivo y Cognos","No cuadra cálculo realizado contra Instructivo"), "Validación correcta"))))) -> Validación correcta | BD6: =IF(BC6="Validación correcta","Ningún comentario",IF(BC6="No cuadran el Instructivo de Cobro y el monto de Cognos","Inconsistencia en los datos de origen","Inconsistencia entre datos de origen y cálculo")) -> Ningún comentario | BE6: Actual | BF6: Procesado
A7: 8000251081 | B7: 3200629676 | C7: RETIRO POR DESEMPLEO IMSS | D7: CON IMAGENES COMPLETAS | E7: 44120.472 | F7: 12910.2 | G7: 0 | H7: 12088914515 | I7: SEEJ890609HGTGSS04 | J7: RETIRO PARCIAL IMSS | K7: Titular/Trabajador | L7: SEEJ890609HGTGSS04 | M7: IRAPUATO | N7: 20201016 11:16:10 | T7: 1 | U7: 21336612483457 | W7: 202010161111090298 | Y7: 12910.2 | Z7: =IF(Y7=F7,"OK","Error 1") -> OK | AA7: Pago único | AC7: =IF(AA7="Pago 1",AB7+Y7,"0") -> 0 | AD7: 44120 | AE7: =IF(V7="SUBSECUENTE","No aplica",VLOOKUP(YEAR(AD7),'SALARIO MINIMO'!A1:B100,2,FALSE)) -> 123.22 | AF7: =IF(V7="SUBSECUENTE","No aplica",IF(YEAR(AD7)=2016,VLOOKUP(YEAR(AD7),UMA!A1:B100,2,FALSE),IF(MONTH(AD7)=1,VLOOKUP((YEAR(AD7))-1,UMA!A1:B100,2,FALSE),VLOOKUP(YEAR(AD7),UMA!A1:B100,2,FALSE)))) -> 86.88 | AG7: =IF(V7="SUBSECUENTE","No aplica",IFERROR(IF(SEARCH("desempleo",C7),AE7*30*10),AE7*30)) -> 36966 | AH7: =IF(V7="SUBSECUENTE","No aplica",IFERROR(IF(SEARCH("desempleo",C7),AF7*30*10),AF7*30)) -> 26064 | AI7: =IF(V7="SUBSECUENTE","No aplica",IF(AA7="Pago único",IF(AG7=Y7,"OK_SM",IF(AH7=Y7,"OK_UMA","Error Validacion 1")),IF(AG7=AC7,"OK_SM",IF(AH7=AC7,"OK_UMA","Error Validacion 1")))) -> Error Validacion 1 | AJ7: =N7 -> 20201016 11:16:10 | AK7: 430.34 | AL7: 221.78 | AM7: =IF(C7="RETIRO POR MATRIMONIO IMSS", 0,AK7*30) -> 12910.2 | AN7: =IF(C7="RETIRO POR MATRIMONIO IMSS", 0,AL7*90) -> 19960.2 | AO7: =IF(V7="SUBSECUENTE","No aplica",IF(AA7="Pago único",IF(AM7=Y7,"OK_SALA",IF(AN7=Y7,"OK_SALB","Revisar_11.5%")),IF(AM7=AC7,"OK_SALA",IF(AN7=AC7,"OK_SALB","Revisar_11.5%")))) -> OK_SALA | AP7: 3959.961 | AQ7: PROF-85 | AR7: 13.238638 | AS7: =AP7*AR7 -> 52424.49 | AT7: =IF(V7="SUBSECUENTE","No aplica",IF(AO7="OK_SALA","SAL_A",IF(AO7="OK_SALB","SAL_B",IF(AO7="Revisar_11.5%",AS7*0.115,"Error Validación 2")))) -> SAL_A | AU7: =IF(V7="SUBSECUENTE","No aplica",IF(AA7="Pago único",IF(AT7<>"SAL_A",IF(ABS(AT7-Y7)<0.02,"OK_11.5%",IF(ABS(AS7-Y7)<0.02,"OK_RCV","Error Validación 4")),"SAL_A"),IF(AT7<>"SAL_A",IF(ABS(AT7-AC7)<0.02,"OK_11.5%",IF(ABS(AS7-AC7)<0.02,"OK_RCV","Error Validación 4")),"SAL_A"))) -> SAL_A | AW7: =IF(V7="SUBSECUENTE",IF(AV7=Y7,"OK_IC","Revisar Pendientes"),"") | AY7: =IF(V7="SUBSECUENTES","No aplica",IF(AX7=Y7,"OK_SUMA","Diferencia pagos en curso")) -> Diferencia pagos en curso | AZ7: =IF(AA7="Pago 1",IF(AI7="OK_SM",AG7,IF(AI7="OK_UMA",AH7,IF(AO7="OK_SALA",AM7,IF(AO7="OK_SALB",AN7,IF(AU7="OK_11.5%",AT7,IF(AU7="OK_RCV",AS7,"Error en validación")))))),"No aplica") -> No aplica | BA7: =IF(ISNUMBER(AZ7),"OK_cálculo pago 1",AZ7) -> No aplica | BB7: =IF(AW7="OK_IC",AV7,IF(AY7="OK_SUMA",AX7,IF(AI7="OK_SM",AG7,IF(AI7="OK_UMA",AH7,IF(AO7="OK_SALA",AM7,IF(AO7="OK_SALB",AN7,IF(AU7="OK_11.5%",AT7,IF(AU7="OK_RCV",AS7,"Error en validación")))))))) -> 12910.2 | BC7: =IF(Z7="Error 1","No cuadran el Instructivo de Cobro y el monto de Cognos",IF(AND(AW7="Revisar Pendientes",AY7<>"OK_SUMA"),"Diferencia entre instructivo de cobro actual y de primer pago",IF(AI7<>"Error Validacion 1","Validación correcta",IF(OR(AO7="OK_SALA",AO7="OK_SALB"),"Validación correcta", IF(AU7="Error Validación 4", IF(AA7="Pago único","No cuadra el cálculo realizado contra Instructivo y Cognos","No cuadra cálculo realizado contra Instructivo"), "Validación correcta"))))) -> Validación correcta | BD7: =IF(BC7="Validación correcta","Ningún comentario",IF(BC7="No cuadran el Instructivo de Cobro y el monto de Cognos","Inconsistencia en los datos de origen","Inconsistencia entre datos de origen y cálculo")) -> Ningún comentario | BE7: Actual | BF7: Procesado
A8: 8000251119 | B8: 3200390850 | C8: RETIRO POR DESEMPLEO IMSS | D8: CON IMAGENES COMPLETAS | E8: 44120.484 | F8: 23464.2 | G8: 0 | H8: 65897277813 | I8: ROVA730817HVZLSL01 | J8: RETIRO PARCIAL IMSS | K8: Titular/Trabajador | L8: ROVA730817HVZLSL01 | M8: VERACRUZ | N8: 20201016 11:32:58 | T8: 1 | U8: 74776832023853 | W8: 202010161125390582 | Y8: 23464.2 | Z8: =IF(Y8=F8,"OK","Error 1") -> OK | AA8: Pago único | AC8: =IF(AA8="Pago 1",AB8+Y8,"0") -> 0 | AD8: 44120 | AE8: =IF(V8="SUBSECUENTE","No aplica",VLOOKUP(YEAR(AD8),'SALARIO MINIMO'!A1:B100,2,FALSE)) -> 123.22 | AF8: =IF(V8="SUBSECUENTE","No aplica",IF(YEAR(AD8)=2016,VLOOKUP(YEAR(AD8),UMA!A1:B100,2,FALSE),IF(MONTH(AD8)=1,VLOOKUP((YEAR(AD8))-1,UMA!A1:B100,2,FALSE),VLOOKUP(YEAR(AD8),UMA!A1:B100,2,FALSE)))) -> 86.88 | AG8: =IF(V8="SUBSECUENTE","No aplica",IFERROR(IF(SEARCH("desempleo",C8),AE8*30*10),AE8*30)) -> 36966 | AH8: =IF(V8="SUBSECUENTE","No aplica",IFERROR(IF(SEARCH("desempleo",C8),AF8*30*10),AF8*30)) -> 26064 | AI8: =IF(V8="SUBSECUENTE","No aplica",IF(AA8="Pago único",IF(AG8=Y8,"OK_SM",IF(AH8=Y8,"OK_UMA","Error Validacion 1")),IF(AG8=AC8,"OK_SM",IF(AH8=AC8,"OK_UMA","Error Validacion 1")))) -> Error Validacion 1 | AJ8: =N8 -> 20201016 11:32:58 | AK8: 782.14 | AL8: 1045.9 | AM8: =IF(C8="RETIRO POR MATRIMONIO IMSS", 0,AK8*30) -> 23464.2 | AN8: =IF(C8="RETIRO POR MATRIMONIO IMSS", 0,AL8*90) -> 94131 | AO8: =IF(V8="SUBSECUENTE","No aplica",IF(AA8="Pago único",IF(AM8=Y8,"OK_SALA",IF(AN8=Y8,"OK_SALB","Revisar_11.5%")),IF(AM8=AC8,"OK_SALA",IF(AN8=AC8,"OK_SALB","Revisar_11.5%")))) -> OK_SALA | AP8: 59983.584 | AQ8: PROF-70 | AR8: 10.849608 | AS8: =AP8*AR8 -> 650798.38 | AT8: =IF(V8="SUBSECUENTE","No aplica",IF(AO8="OK_SALA","SAL_A",IF(AO8="OK_SALB","SAL_B",IF(AO8="Revisar_11.5%",AS8*0.115,"Error Validación 2")))) -> SAL_A | AU8: =IF(V8="SUBSECUENTE","No aplica",IF(AA8="Pago único",IF(AT8<>"SAL_A",IF(ABS(AT8-Y8)<0.02,"OK_11.5%",IF(ABS(AS8-Y8)<0.02,"OK_RCV","Error Validación 4")),"SAL_A"),IF(AT8<>"SAL_A",IF(ABS(AT8-AC8)<0.02,"OK_11.5%",IF(ABS(AS8-AC8)<0.02,"OK_RCV","Error Validación 4")),"SAL_A"))) -> SAL_A | AW8: =IF(V8="SUBSECUENTE",IF(AV8=Y8,"OK_IC","Revisar Pendientes"),"") | AY8: =IF(V8="SUBSECUENTES","No aplica",IF(AX8=Y8,"OK_SUMA","Diferencia pagos en curso")) -> Diferencia pagos en curso | AZ8: =IF(AA8="Pago 1",IF(AI8="OK_SM",AG8,IF(AI8="OK_UMA",AH8,IF(AO8="OK_SALA",AM8,IF(AO8="OK_SALB",AN8,IF(AU8="OK_11.5%",AT8,IF(AU8="OK_RCV",AS8,"Error en validación")))))),"No aplica") -> No aplica | BA8: =IF(ISNUMBER(AZ8),"OK_cálculo pago 1",AZ8) -> No aplica | BB8: =IF(AW8="OK_IC",AV8,IF(AY8="OK_SUMA",AX8,IF(AI8="OK_SM",AG8,IF(AI8="OK_UMA",AH8,IF(AO8="OK_SALA",AM8,IF(AO8="OK_SALB",AN8,IF(AU8="OK_11.5%",AT8,IF(AU8="OK_RCV",AS8,"Error en validación")))))))) -> 23464.2 | BC8: =IF(Z8="Error 1","No cuadran el Instructivo de Cobro y el monto de Cognos",IF(AND(AW8="Revisar Pendientes",AY8<>"OK_SUMA"),"Diferencia entre instructivo de cobro actual y de primer pago",IF(AI8<>"Error Validacion 1","Validación correcta",IF(OR(AO8="OK_SALA",AO8="OK_SALB"),"Validación correcta", IF(AU8="Error Validación 4", IF(AA8="Pago único","No cuadra el cálculo realizado contra Instructivo y Cognos","No cuadra cálculo realizado contra Instructivo"), "Validación correcta"))))) -> Validación correcta | BD8: =IF(BC8="Validación correcta","Ningún comentario",IF(BC8="No cuadran el Instructivo de Cobro y el monto de Cognos","Inconsistencia en los datos de origen","Inconsistencia entre datos de origen y cálculo")) -> Ningún comentario | BE8: Actual | BF8: Procesado
A9: 8000251234 | B9: 3200043721 | C9: RETIRO DE AYUDA PARA GASTOS DE MATRIMONIO IMSS | D9: ACEPTADO MC | E9: 44120.523 | F9: 2606.4 | G9: 0 | H9: 24907424667 | I9: ROCR741221HSRBNF07 | J9: RETIRO PARCIAL IMSS | K9: Titular/Trabajador | L9: ROCR741221HSRBNF07 | M9: HERMOSILLO | N9: 20201016 12:27:20 | T9: 1 | U9: 95332930605332 | W9: 202010161220420033 | Y9: 2606.4 | Z9: =IF(Y9=F9,"OK","Error 1") -> OK | AA9: Pago único | AC9: =IF(AA9="Pago 1",AB9+Y9,"0") -> 0 | AD9: 44109 | AE9: =IF(V9="SUBSECUENTE","No aplica",VLOOKUP(YEAR(AD9),'SALARIO MINIMO'!A1:B100,2,FALSE)) -> 123.22 | AF9: =IF(V9="SUBSECUENTE","No aplica",IF(YEAR(AD9)=2016,VLOOKUP(YEAR(AD9),UMA!A1:B100,2,FALSE),IF(MONTH(AD9)=1,VLOOKUP((YEAR(AD9))-1,UMA!A1:B100,2,FALSE),VLOOKUP(YEAR(AD9),UMA!A1:B100,2,FALSE)))) -> 86.88 | AG9: =IF(V9="SUBSECUENTE","No aplica",IFERROR(IF(SEARCH("desempleo",C9),AE9*30*10),AE9*30)) -> 3696.6 | AH9: =IF(V9="SUBSECUENTE","No aplica",IFERROR(IF(SEARCH("desempleo",C9),AF9*30*10),AF9*30)) -> 2606.4 | AI9: =IF(V9="SUBSECUENTE","No aplica",IF(AA9="Pago único",IF(AG9=Y9,"OK_SM",IF(AH9=Y9,"OK_UMA","Error Validacion 1")),IF(AG9=AC9,"OK_SM",IF(AH9=AC9,"OK_UMA","Error Validacion 1")))) -> OK_UMA | AJ9: =N9 -> 20201016 12:27:20 | AK9: 2606.4 | AL9: 0 | AM9: =IF(C9="RETIRO POR MATRIMONIO IMSS", 0,AK9*30) -> 78192 | AN9: =IF(C9="RETIRO POR MATRIMONIO IMSS", 0,AL9*90) -> 0 | AO9: =IF(V9="SUBSECUENTE","No aplica",IF(AA9="Pago único",IF(AM9=Y9,"OK_SALA",IF(AN9=Y9,"OK_SALB","Revisar_11.5%")),IF(AM9=AC9,"OK_SALA",IF(AN9=AC9,"OK_SALB","Revisar_11.5%")))) -> Revisar_11.5% | AP9: 28749.079 | AQ9: PROF-70 | AR9: 10.849608 | AS9: =AP9*AR9 -> 311916.24 | AT9: =IF(V9="SUBSECUENTE","No aplica",IF(AO9="OK_SALA","SAL_A",IF(AO9="OK_SALB","SAL_B",IF(AO9="Revisar_11.5%",AS9*0.115,"Error Validación 2")))) -> 35870.367 | AU9: =IF(V9="SUBSECUENTE","No aplica",IF(AA9="Pago único",IF(AT9<>"SAL_A",IF(ABS(AT9-Y9)<0.02,"OK_11.5%",IF(ABS(AS9-Y9)<0.02,"OK_RCV","Error Validación 4")),"SAL_A"),IF(AT9<>"SAL_A",IF(ABS(AT9-AC9)<0.02,"OK_11.5%",IF(ABS(AS9-AC9)<0.02,"OK_RCV","Error Validación 4")),"SAL_A"))) -> Error Validación 4 | AW9: =IF(V9="SUBSECUENTE",IF(AV9=Y9,"OK_IC","Revisar Pendientes"),"") | AY9: =IF(V9="SUBSECUENTES","No aplica",IF(AX9=Y9,"OK_SUMA","Diferencia pagos en curso")) -> Diferencia pagos en curso | AZ9: =IF(AA9="Pago 1",IF(AI9="OK_SM",AG9,IF(AI9="OK_UMA",AH9,IF(AO9="OK_SALA",AM9,IF(AO9="OK_SALB",AN9,IF(AU9="OK_11.5%",AT9,IF(AU9="OK_RCV",AS9,"Error en validación")))))),"No aplica") -> No aplica | BA9: =IF(ISNUMBER(AZ9),"OK_cálculo pago 1",AZ9) -> No aplica | BB9: =IF(AW9="OK_IC",AV9,IF(AY9="OK_SUMA",AX9,IF(AI9="OK_SM",AG9,IF(AI9="OK_UMA",AH9,IF(AO9="OK_SALA",AM9,IF(AO9="OK_SALB",AN9,IF(AU9="OK_11.5%",AT9,IF(AU9="OK_RCV",AS9,"Error en validación")))))))) -> 2606.4 | BC9: =IF(Z9="Error 1","No cuadran el Instructivo de Cobro y el monto de Cognos",IF(AND(AW9="Revisar Pendientes",AY9<>"OK_SUMA"),"Diferencia entre instructivo de cobro actual y de primer pago",IF(AI9<>"Error Validacion 1","Validación correcta",IF(OR(AO9="OK_SALA",AO9="OK_SALB"),"Validación correcta", IF(AU9="Error Validación 4", IF(AA9="Pago único","No cuadra el cálculo realizado contra Instructivo y Cognos","No cuadra cálculo realizado contra Instructivo"), "Validación correcta"))))) -> Validación correcta | BD9: =IF(BC9="Validación correcta","Ningún comentario",IF(BC9="No cuadran el Instructivo de Cobro y el monto de Cognos","Inconsistencia en los datos de origen","Inconsistencia entre datos de origen y cálculo")) -> Ningún comentario | BE9: Actual | BF9: Procesado
A10: 8000251394 | B10: 0550906892 | C10: RETIRO POR DESEMPLEO IMSS | D10: CON IMAGENES COMPLETAS | E10: 44120.553 | F10: 6870.6 | G10: 0 | H10: 56927464364 | I10: GAGF751115HJCLZR06 | J10: RETIRO PARCIAL IMSS | K10: Titular/Trabajador | L10: GAGF751115HJCLZR06 | M10: GUADALAJARA | N10: 20201016 13:08:35 | T10: 1 | U10: 85654536756332 | W10: 202010161300090260 | Y10: 6870.6 | Z10: =IF(Y10=F10,"OK","Error 1") -> OK | AA10: Pago único | AC10: =IF(AA10="Pago 1",AB10+Y10,"0") -> 0 | AD10: 44120 | AE10: =IF(V10="SUBSECUENTE","No aplica",VLOOKUP(YEAR(AD10),'SALARIO MINIMO'!A1:B100,2,FALSE)) -> 123.22 | AF10: =IF(V10="SUBSECUENTE","No aplica",IF(YEAR(AD10)=2016,VLOOKUP(YEAR(AD10),UMA!A1:B100,2,FALSE),IF(MONTH(AD10)=1,VLOOKUP((YEAR(AD10))-1,UMA!A1:B100,2,FALSE),VLOOKUP(YEAR(AD10),UMA!A1:B100,2,FALSE)))) -> 86.88 | AG10: =IF(V10="SUBSECUENTE","No aplica",IFERROR(IF(SEARCH("desempleo",C10),AE10*30*10),AE10*30)) -> 36966 | AH10: =IF(V10="SUBSECUENTE","No aplica",IFERROR(IF(SEARCH("desempleo",C10),AF10*30*10),AF10*30)) -> 26064 | AI10: =IF(V10="SUBSECUENTE","No aplica",IF(AA10="Pago único",IF(AG10=Y10,"OK_SM",IF(AH10=Y10,"OK_UMA","Error Validacion 1")),IF(AG10=AC10,"OK_SM",IF(AH10=AC10,"OK_UMA","Error Validacion 1")))) -> Error Validacion 1 | AJ10: =N10 -> 20201016 13:08:35 | AK10: 229.02 | AL10: 98.98 | AM10: =IF(C10="RETIRO POR MATRIMONIO IMSS", 0,AK10*30) -> 6870.6 | AN10: =IF(C10="RETIRO POR MATRIMONIO IMSS", 0,AL10*90) -> 8908.2 | AO10: =IF(V10="SUBSECUENTE","No aplica",IF(AA10="Pago único",IF(AM10=Y10,"OK_SALA",IF(AN10=Y10,"OK_SALB","Revisar_11.5%")),IF(AM10=AC10,"OK_SALA",IF(AN10=AC10,"OK_SALB","Revisar_11.5%")))) -> OK_SALA | AP10: 1364.4191 | AQ10: PROF-75 | AR10: 12.09101 | AS10: =AP10*AR10 -> 16497.205 | AT10: =IF(V10="SUBSECUENTE","No aplica",IF(AO10="OK_SALA","SAL_A",IF(AO10="OK_SALB","SAL_B",IF(AO10="Revisar_11.5%",AS10*0.115,"Error Validación 2")))) -> SAL_A | AU10: =IF(V10="SUBSECUENTE","No aplica",IF(AA10="Pago único",IF(AT10<>"SAL_A",IF(ABS(AT10-Y10)<0.02,"OK_11.5%",IF(ABS(AS10-Y10)<0.02,"OK_RCV","Error Validación 4")),"SAL_A"),IF(AT10<>"SAL_A",IF(ABS(AT10-AC10)<0.02,"OK_11.5%",IF(ABS(AS10-AC10)<0.02,"OK_RCV","Error Validación 4")),"SAL_A"))) -> SAL_A | AW10: =IF(V10="SUBSECUENTE",IF(AV10=Y10,"OK_IC","Revisar Pendientes"),"") | AY10: =IF(V10="SUBSECUENTES","No aplica",IF(AX10=Y10,"OK_SUMA","Diferencia pagos en curso")) -> Diferencia pagos en curso | AZ10: =IF(AA10="Pago 1",IF(AI10="OK_SM",AG10,IF(AI10="OK_UMA",AH10,IF(AO10="OK_SALA",AM10,IF(AO10="OK_SALB",AN10,IF(AU10="OK_11.5%",AT10,IF(AU10="OK_RCV",AS10,"Error en validación")))))),"No aplica") -> No aplica | BA10: =IF(ISNUMBER(AZ10),"OK_cálculo pago 1",AZ10) -> No aplica | BB10: =IF(AW10="OK_IC",AV10,IF(AY10="OK_SUMA",AX10,IF(AI10="OK_SM",AG10,IF(AI10="OK_UMA",AH10,IF(AO10="OK_SALA",AM10,IF(AO10="OK_SALB",AN10,IF(AU10="OK_11.5%",AT10,IF(AU10="OK_RCV",AS10,"Error en validación")))))))) -> 6870.6 | BC10: =IF(Z10="Error 1","No cuadran el Instructivo de Cobro y el monto de Cognos",IF(AND(AW10="Revisar Pendientes",AY10<>"OK_SUMA"),"Diferencia entre instructivo de cobro actual y de primer pago",IF(AI10<>"Error Validacion 1","Validación correcta",IF(OR(AO10="OK_SALA",AO10="OK_SALB"),"Validación correcta", IF(AU10="Error Validación 4", IF(AA10="Pago único","No cuadra el cálculo realizado contra Instructivo y Cognos","No cuadra cálculo realizado contra Instructivo"), "Validación correcta"))))) -> Validación correcta | BD10: =IF(BC10="Validación correcta","Ningún comentario",IF(BC10="No cuadran el Instructivo de Cobro y el monto de Cognos","Inconsistencia en los datos de origen","Inconsistencia entre datos de origen y cálculo")) -> Ningún comentario | BE10: Actual | BF10: Procesado
A11: 8000251522 | B11: 1840007958 | C11: RETIRO POR DESEMPLEO IMSS | D11: CON IMAGENES COMPLETAS | E11: 44120.605 | F11: 7575.6 | G11: 0 | H11: 20047400179 | I11: AIAP740402MSRBNT08 | J11: RETIRO PARCIAL IMSS | K11: Titular/Trabajador | L11: AIAP740402MSRBNT08 | M11: TIJUANA | N11: 20201016 14:27:43 | T11: 1 | U11: 69583883594481 | W11: 202010161412524139 | Y11: 7575.6 | Z11: =IF(Y11=F11,"OK","Error 1") -> OK | AA11: Pago único | AC11: =IF(AA11="Pago 1",AB11+Y11,"0") -> 0 | AD11: 44120 | AE11: =IF(V11="SUBSECUENTE","No aplica",VLOOKUP(YEAR(AD11),'SALARIO MINIMO'!A1:B100,2,FALSE)) -> 123.22 | AF11: =IF(V11="SUBSECUENTE","No aplica",IF(YEAR(AD11)=2016,VLOOKUP(YEAR(AD11),UMA!A1:B100,2,FALSE),IF(MONTH(AD11)=1,VLOOKUP((YEAR(AD11))-1,UMA!A1:B100,2,FALSE),VLOOKUP(YEAR(AD11),UMA!A1:B100,2,FALSE)))) -> 86.88 | AG11: =IF(V11="SUBSECUENTE","No aplica",IFERROR(IF(SEARCH("desempleo",C11),AE11*30*10),AE11*30)) -> 36966 | AH11: =IF(V11="SUBSECUENTE","No aplica",IFERROR(IF(SEARCH("desempleo",C11),AF11*30*10),AF11*30)) -> 26064 | AI11: =IF(V11="SUBSECUENTE","No aplica",IF(AA11="Pago único",IF(AG11=Y11,"OK_SM",IF(AH11=Y11,"OK_UMA","Error Validacion 1")),IF(AG11=AC11,"OK_SM",IF(AH11=AC11,"OK_UMA","Error Validacion 1")))) -> Error Validacion 1 | AJ11: =N11 -> 20201016 14:27:43 | AK11: 252.52 | AL11: 166.24 | AM11: =IF(C11="RETIRO POR MATRIMONIO IMSS", 0,AK11*30) -> 7575.6 | AN11: =IF(C11="RETIRO POR MATRIMONIO IMSS", 0,AL11*90) -> 14961.6 | AO11: =IF(V11="SUBSECUENTE","No aplica",IF(AA11="Pago único",IF(AM11=Y11,"OK_SALA",IF(AN11=Y11,"OK_SALB","Revisar_11.5%")),IF(AM11=AC11,"OK_SALA",IF(AN11=AC11,"OK_SALB","Revisar_11.5%")))) -> OK_SALA | AP11: 3023.418 | AQ11: PROF-70 | AR11: 10.849608 | AS11: =AP11*AR11 -> 32802.901 | AT11: =IF(V11="SUBSECUENTE","No aplica",IF(AO11="OK_SALA","SAL_A",IF(AO11="OK_SALB","SAL_B",IF(AO11="Revisar_11.5%",AS11*0.115,"Error Validación 2")))) -> SAL_A | AU11: =IF(V11="SUBSECUENTE","No aplica",IF(AA11="Pago único",IF(AT11<>"SAL_A",IF(ABS(AT11-Y11)<0.02,"OK_11.5%",IF(ABS(AS11-Y11)<0.02,"OK_RCV","Error Validación 4")),"SAL_A"),IF(AT11<>"SAL_A",IF(ABS(AT11-AC11)<0.02,"OK_11.5%",IF(ABS(AS11-AC11)<0.02,"OK_RCV","Error Validación 4")),"SAL_A"))) -> SAL_A | AW11: =IF(V11="SUBSECUENTE",IF(AV11=Y11,"OK_IC","Revisar Pendientes"),"") | AY11: =IF(V11="SUBSECUENTES","No aplica",IF(AX11=Y11,"OK_SUMA","Diferencia pagos en curso")) -> Diferencia pagos en curso | AZ11: =IF(AA11="Pago 1",IF(AI11="OK_SM",AG11,IF(AI11="OK_UMA",AH11,IF(AO11="OK_SALA",AM11,IF(AO11="OK_SALB",AN11,IF(AU11="OK_11.5%",AT11,IF(AU11="OK_RCV",AS11,"Error en validación")))))),"No aplica") -> No aplica | BA11: =IF(ISNUMBER(AZ11),"OK_cálculo pago 1",AZ11) -> No aplica | BB11: =IF(AW11="OK_IC",AV11,IF(AY11="OK_SUMA",AX11,IF(AI11="OK_SM",AG11,IF(AI11="OK_UMA",AH11,IF(AO11="OK_SALA",AM11,IF(AO11="OK_SALB",AN11,IF(AU11="OK_11.5%",AT11,IF(AU11="OK_RCV",AS11,"Error en validación")))))))) -> 7575.6 | BC11: =IF(Z11="Error 1","No cuadran el Instructivo de Cobro y el monto de Cognos",IF(AND(AW11="Revisar Pendientes",AY11<>"OK_SUMA"),"Diferencia entre instructivo de cobro actual y de primer pago",IF(AI11<>"Error Validacion 1","Validación correcta",IF(OR(AO11="OK_SALA",AO11="OK_SALB"),"Validación correcta", IF(AU11="Error Validación 4", IF(AA11="Pago único","No cuadra el cálculo realizado contra Instructivo y Cognos","No cuadra cálculo realizado contra Instructivo"), "Validación correcta"))))) -> Validación correcta | BD11: =IF(BC11="Validación correcta","Ningún comentario",IF(BC11="No cuadran el Instructivo de Cobro y el monto de Cognos","Inconsistencia en los datos de origen","Inconsistencia entre datos de origen y cálculo")) -> Ningún comentario | BE11: Actual | BF11: Procesado
A12: 8000250751 | B12: 1100031358 | C12: RETIRO POR DESEMPLEO IMSS | D12: CON IMAGENES COMPLETAS | E12: 44120.425 | F12: 26064 | G12: 0 | H12: 39967827229 | I12: VILN780712MDFLPN05 | J12: RETIRO PARCIAL IMSS | K12: Titular/Trabajador | L12: VILN780712MDFLPN05 | M12: GUADALAJARA | N12: 20201016 10:04:20 | T12: 1 | U12: 40580681201763 | W12: 202010160956550376 | Y12: 26064 | Z12: =IF(Y12=F12,"OK","Error 1") -> OK | AA12: Pago único | AC12: =IF(AA12="Pago 1",AB12+Y12,"0") -> 0 | AD12: 44120 | AE12: =IF(V12="SUBSECUENTE","No aplica",VLOOKUP(YEAR(AD12),'SALARIO MINIMO'!A1:B100,2,FALSE)) -> 123.22 | AF12: =IF(V12="SUBSECUENTE","No aplica",IF(YEAR(AD12)=2016,VLOOKUP(YEAR(AD12),UMA!A1:B100,2,FALSE),IF(MONTH(AD12)=1,VLOOKUP((YEAR(AD12))-1,UMA!A1:B100,2,FALSE),VLOOKUP(YEAR(AD12),UMA!A1:B100,2,FALSE)))) -> 86.88 | AG12: =IF(V12="SUBSECUENTE","No aplica",IFERROR(IF(SEARCH("desempleo",C12),AE12*30*10),AE12*30)) -> 36966 | AH12: =IF(V12="SUBSECUENTE","No aplica",IFERROR(IF(SEARCH("desempleo",C12),AF12*30*10),AF12*30)) -> 26064 | AI12: =IF(V12="SUBSECUENTE","No aplica",IF(AA12="Pago único",IF(AG12=Y12,"OK_SM",IF(AH12=Y12,"OK_UMA","Error Validacion 1")),IF(AG12=AC12,"OK_SM",IF(AH12=AC12,"OK_UMA","Error Validacion 1")))) -> OK_UMA | AJ12: =N12 -> 20201016 10:04:20 | AK12: 896.59 | AL12: 653.49 | AM12: =IF(C12="RETIRO POR MATRIMONIO IMSS", 0,AK12*30) -> 26897.7 | AN12: =IF(C12="RETIRO POR MATRIMONIO IMSS", 0,AL12*90) -> 58814.1 | AO12: =IF(V12="SUBSECUENTE","No aplica",IF(AA12="Pago único",IF(AM12=Y12,"OK_SALA",IF(AN12=Y12,"OK_SALB","Revisar_11.5%")),IF(AM12=AC12,"OK_SALA",IF(AN12=AC12,"OK_SALB","Revisar_11.5%")))) -> Revisar_11.5% | AP12: 13166.31 | AQ12: PROF-75 | AR12: 12.09101 | AS12: =AP12*AR12 -> 159193.99 | AT12: =IF(V12="SUBSECUENTE","No aplica",IF(AO12="OK_SALA","SAL_A",IF(AO12="OK_SALB","SAL_B",IF(AO12="Revisar_11.5%",AS12*0.115,"Error Validación 2")))) -> 18307.309 | AU12: =IF(V12="SUBSECUENTE","No aplica",IF(AA12="Pago único",IF(AT12<>"SAL_A",IF(ABS(AT12-Y12)<0.02,"OK_11.5%",IF(ABS(AS12-Y12)<0.02,"OK_RCV","Error Validación 4")),"SAL_A"),IF(AT12<>"SAL_A",IF(ABS(AT12-AC12)<0.02,"OK_11.5%",IF(ABS(AS12-AC12)<0.02,"OK_RCV","Error Validación 4")),"SAL_A"))) -> Error Validación 4 | AW12: =IF(V12="SUBSECUENTE",IF(AV12=Y12,"OK_IC","Revisar Pendientes"),"") | AY12: =IF(V12="SUBSECUENTES","No aplica",IF(AX12=Y12,"OK_SUMA","Diferencia pagos en curso")) -> Diferencia pagos en curso | AZ12: =IF(AA12="Pago 1",IF(AI12="OK_SM",AG12,IF(AI12="OK_UMA",AH12,IF(AO12="OK_SALA",AM12,IF(AO12="OK_SALB",AN12,IF(AU12="OK_11.5%",AT12,IF(AU12="OK_RCV",AS12,"Error en validación")))))),"No aplica") -> No aplica | BA12: =IF(ISNUMBER(AZ12),"OK_cálculo pago 1",AZ12) -> No aplica | BB12: =IF(AW12="OK_IC",AV12,IF(AY12="OK_SUMA",AX12,IF(AI12="OK_SM",AG12,IF(AI12="OK_UMA",AH12,IF(AO12="OK_SALA",AM12,IF(AO12="OK_SALB",AN12,IF(AU12="OK_11.5%",AT12,IF(AU12="OK_RCV",AS12,"Error en validación")))))))) -> 26064 | BC12: =IF(Z12="Error 1","No cuadran el Instructivo de Cobro y el monto de Cognos",IF(AND(AW12="Revisar Pendientes",AY12<>"OK_SUMA"),"Diferencia entre instructivo de cobro actual y de primer pago",IF(AI12<>"Error Validacion 1","Validación correcta",IF(OR(AO12="OK_SALA",AO12="OK_SALB"),"Validación correcta", IF(AU12="Error Validación 4", IF(AA12="Pago único","No cuadra el cálculo realizado contra Instructivo y Cognos","No cuadra cálculo realizado contra Instructivo"), "Validación correcta"))))) -> Validación correcta | BD12: =IF(BC12="Validación correcta","Ningún comentario",IF(BC12="No cuadran el Instructivo de Cobro y el monto de Cognos","Inconsistencia en los datos de origen","Inconsistencia entre datos de origen y cálculo")) -> Ningún comentario | BE12: Actual | BF12: Procesado
A13: 8000250604 | B13: 3300159793 | C13: RETIRO DE AYUDA PARA GASTOS DE MATRIMONIO IMSS | D13: ACEPTADO MC | E13: 44120.353 | F13: 2606.4 | G13: 0 | H13: 92109236445 | I13: BEHK920812MDFRRR01 | J13: RETIRO PARCIAL IMSS | K13: Titular/Trabajador | L13: BEHK920812MDFRRR01 | M13: TOLUCA | N13: 20201016 08:16:58 | T13: 1 | U13: 37553098727553 | W13: 202010160812170001 | Y13: 2606.4 | Z13: =IF(Y13=F13,"OK","Error 1") -> OK | AA13: Pago único | AC13: =IF(AA13="Pago 1",AB13+Y13,"0") -> 0 | AD13: 44106 | AE13: =IF(V13="SUBSECUENTE","No aplica",VLOOKUP(YEAR(AD13),'SALARIO MINIMO'!A1:B100,2,FALSE)) -> 123.22 | AF13: =IF(V13="SUBSECUENTE","No aplica",IF(YEAR(AD13)=2016,VLOOKUP(YEAR(AD13),UMA!A1:B100,2,FALSE),IF(MONTH(AD13)=1,VLOOKUP((YEAR(AD13))-1,UMA!A1:B100,2,FALSE),VLOOKUP(YEAR(AD13),UMA!A1:B100,2,FALSE)))) -> 86.88 | AG13: =IF(V13="SUBSECUENTE","No aplica",IFERROR(IF(SEARCH("desempleo",C13),AE13*30*10),AE13*30)) -> 3696.6 | AH13: =IF(V13="SUBSECUENTE","No aplica",IFERROR(IF(SEARCH("desempleo",C13),AF13*30*10),AF13*30)) -> 2606.4 | AI13: =IF(V13="SUBSECUENTE","No aplica",IF(AA13="Pago único",IF(AG13=Y13,"OK_SM",IF(AH13=Y13,"OK_UMA","Error Validacion 1")),IF(AG13=AC13,"OK_SM",IF(AH13=AC13,"OK_UMA","Error Validacion 1")))) -> OK_UMA | AJ13: =N13 -> 20201016 08:16:58 | AK13: 2606.4 | AL13: 0 | AM13: =IF(C13="RETIRO POR MATRIMONIO IMSS", 0,AK13*30) -> 78192 | AN13: =IF(C13="RETIRO POR MATRIMONIO IMSS", 0,AL13*90) -> 0 | AO13: =IF(V13="SUBSECUENTE","No aplica",IF(AA13="Pago único",IF(AM13=Y13,"OK_SALA",IF(AN13=Y13,"OK_SALB","Revisar_11.5%")),IF(AM13=AC13,"OK_SALA",IF(AN13=AC13,"OK_SALB","Revisar_11.5%")))) -> Revisar_11.5% | AP13: 7184.0364 | AQ13: PROF-90 | AR13: 13.148607 | AS13: =AP13*AR13 -> 94460.071 | AT13: =IF(V13="SUBSECUENTE","No aplica",IF(AO13="OK_SALA","SAL_A",IF(AO13="OK_SALB","SAL_B",IF(AO13="Revisar_11.5%",AS13*0.115,"Error Validación 2")))) -> 10862.908 | AU13: =IF(V13="SUBSECUENTE","No aplica",IF(AA13="Pago único",IF(AT13<>"SAL_A",IF(ABS(AT13-Y13)<0.02,"OK_11.5%",IF(ABS(AS13-Y13)<0.02,"OK_RCV","Error Validación 4")),"SAL_A"),IF(AT13<>"SAL_A",IF(ABS(AT13-AC13)<0.02,"OK_11.5%",IF(ABS(AS13-AC13)<0.02,"OK_RCV","Error Validación 4")),"SAL_A"))) -> Error Validación 4 | AW13: =IF(V13="SUBSECUENTE",IF(AV13=Y13,"OK_IC","Revisar Pendientes"),"") | AY13: =IF(V13="SUBSECUENTES","No aplica",IF(AX13=Y13,"OK_SUMA","Diferencia pagos en curso")) -> Diferencia pagos en curso | AZ13: =IF(AA13="Pago 1",IF(AI13="OK_SM",AG13,IF(AI13="OK_UMA",AH13,IF(AO13="OK_SALA",AM13,IF(AO13="OK_SALB",AN13,IF(AU13="OK_11.5%",AT13,IF(AU13="OK_RCV",AS13,"Error en validación")))))),"No aplica") -> No aplica | BA13: =IF(ISNUMBER(AZ13),"OK_cálculo pago 1",AZ13) -> No aplica | BB13: =IF(AW13="OK_IC",AV13,IF(AY13="OK_SUMA",AX13,IF(AI13="OK_SM",AG13,IF(AI13="OK_UMA",AH13,IF(AO13="OK_SALA",AM13,IF(AO13="OK_SALB",AN13,IF(AU13="OK_11.5%",AT13,IF(AU13="OK_RCV",AS13,"Error en validación")))))))) -> 2606.4 | BC13: =IF(Z13="Error 1","No cuadran el Instructivo de Cobro y el monto de Cognos",IF(AND(AW13="Revisar Pendientes",AY13<>"OK_SUMA"),"Diferencia entre instructivo de cobro actual y de primer pago",IF(AI13<>"Error Validacion 1","Validación correcta",IF(OR(AO13="OK_SALA",AO13="OK_SALB"),"Validación correcta", IF(AU13="Error Validación 4", IF(AA13="Pago único","No cuadra el cálculo realizado contra Instructivo y Cognos","No cuadra cálculo realizado contra Instructivo"), "Validación correcta"))))) -> Validación correcta | BD13: =IF(BC13="Validación correcta","Ningún comentario",IF(BC13="No cuadran el Instructivo de Cobro y el monto de Cognos","Inconsistencia en los datos de origen","Inconsistencia entre datos de origen y cálculo")) -> Ningún comentario | BE13: Actual | BF13: Procesado
A14: 8000250677 | B14: 3300030382 | C14: RETIRO POR DESEMPLEO IMSS | D14: CON IMAGENES COMPLETAS | E14: 44120.357 | F14: 17699.1 | G14: 0 | H14: 04119008219 | I14: HERA901009HJCRDL03 | J14: RETIRO PARCIAL IMSS | K14: Titular/Trabajador | L14: HERA901009HJCRDL03 | M14: GUADALAJARA | N14: 20201016 08:29:46 | T14: 1 | U14: 34738452496399 | W14: 202010160822410110 | Y14: 17699.1 | Z14: =IF(Y14=F14,"OK","Error 1") -> OK | AA14: Pago único | AC14: =IF(AA14="Pago 1",AB14+Y14,"0") -> 0 | AD14: 44120 | AE14: =IF(V14="SUBSECUENTE","No aplica",VLOOKUP(YEAR(AD14),'SALARIO MINIMO'!A1:B100,2,FALSE)) -> 123.22 | AF14: =IF(V14="SUBSECUENTE","No aplica",IF(YEAR(AD14)=2016,VLOOKUP(YEAR(AD14),UMA!A1:B100,2,FALSE),IF(MONTH(AD14)=1,VLOOKUP((YEAR(AD14))-1,UMA!A1:B100,2,FALSE),VLOOKUP(YEAR(AD14),UMA!A1:B100,2,FALSE)))) -> 86.88 | AG14: =IF(V14="SUBSECUENTE","No aplica",IFERROR(IF(SEARCH("desempleo",C14),AE14*30*10),AE14*30)) -> 36966 | AH14: =IF(V14="SUBSECUENTE","No aplica",IFERROR(IF(SEARCH("desempleo",C14),AF14*30*10),AF14*30)) -> 26064 | AI14: =IF(V14="SUBSECUENTE","No aplica",IF(AA14="Pago único",IF(AG14=Y14,"OK_SM",IF(AH14=Y14,"OK_UMA","Error Validacion 1")),IF(AG14=AC14,"OK_SM",IF(AH14=AC14,"OK_UMA","Error Validacion 1")))) -> Error Validacion 1 | AJ14: =N14 -> 20201016 08:29:46 | AK14: 589.97 | AL14: 495.66 | AM14: =IF(C14="RETIRO POR MATRIMONIO IMSS", 0,AK14*30) -> 17699.1 | AN14: =IF(C14="RETIRO POR MATRIMONIO IMSS", 0,AL14*90) -> 44609.4 | AO14: =IF(V14="SUBSECUENTE","No aplica",IF(AA14="Pago único",IF(AM14=Y14,"OK_SALA",IF(AN14=Y14,"OK_SALB","Revisar_11.5%")),IF(AM14=AC14,"OK_SALA",IF(AN14=AC14,"OK_SALB","Revisar_11.5%")))) -> OK_SALA | AP14: 4576.2659 | AQ14: PROF-90 | AR14: 13.148607 | AS14: =AP14*AR14 -> 60171.522 | AT14: =IF(V14="SUBSECUENTE","No aplica",IF(AO14="OK_SALA","SAL_A",IF(AO14="OK_SALB","SAL_B",IF(AO14="Revisar_11.5%",AS14*0.115,"Error Validación 2")))) -> SAL_A | AU14: =IF(V14="SUBSECUENTE","No aplica",IF(AA14="Pago único",IF(AT14<>"SAL_A",IF(ABS(AT14-Y14)<0.02,"OK_11.5%",IF(ABS(AS14-Y14)<0.02,"OK_RCV","Error Validación 4")),"SAL_A"),IF(AT14<>"SAL_A",IF(ABS(AT14-AC14)<0.02,"OK_11.5%",IF(ABS(AS14-AC14)<0.02,"OK_RCV","Error Validación 4")),"SAL_A"))) -> SAL_A | AW14: =IF(V14="SUBSECUENTE",IF(AV14=Y14,"OK_IC","Revisar Pendientes"),"") | AY14: =IF(V14="SUBSECUENTES","No aplica",IF(AX14=Y14,"OK_SUMA","Diferencia pagos en curso")) -> Diferencia pagos en curso | AZ14: =IF(AA14="Pago 1",IF(AI14="OK_SM",AG14,IF(AI14="OK_UMA",AH14,IF(AO14="OK_SALA",AM14,IF(AO14="OK_SALB",AN14,IF(AU14="OK_11.5%",AT14,IF(AU14="OK_RCV",AS14,"Error en validación")))))),"No aplica") -> No aplica | BA14: =IF(ISNUMBER(AZ14),"OK_cálculo pago 1",AZ14) -> No aplica | BB14: =IF(AW14="OK_IC",AV14,IF(AY14="OK_SUMA",AX14,IF(AI14="OK_SM",AG14,IF(AI14="OK_UMA",AH14,IF(AO14="OK_SALA",AM14,IF(AO14="OK_SALB",AN14,IF(AU14="OK_11.5%",AT14,IF(AU14="OK_RCV",AS14,"Error en validación")))))))) -> 17699.1 | BC14: =IF(Z14="Error 1","No cuadran el Instructivo de Cobro y el monto de Cognos",IF(AND(AW14="Revisar Pendientes",AY14<>"OK_SUMA"),"Diferencia entre instructivo de cobro actual y de primer pago",IF(AI14<>"Error Validacion 1","Validación correcta",IF(OR(AO14="OK_SALA",AO14="OK_SALB"),"Validación correcta", IF(AU14="Error Validación 4", IF(AA14="Pago único","No cuadra el cálculo realizado contra Instructivo y Cognos","No cuadra cálculo realizado contra Instructivo"), "Validación correcta"))))) -> Validación correcta | BD14: =IF(BC14="Validación correcta","Ningún comentario",IF(BC14="No cuadran el Instructivo de Cobro y el monto de Cognos","Inconsistencia en los datos de origen","Inconsistencia entre datos de origen y cálculo")) -> Ningún comentario | BE14: Actual | BF14: Procesado
A15: 8000251396 | B15: 2540024129 | C15: RETIRO DE AYUDA PARA GASTOS DE MATRIMONIO IMSS | D15: ACEPTADO MC | E15: 44120.59 | F15: 2606.4 | G15: 0 | H15: 09947207321 | I15: VAHV720130HCLLRC08 | J15: RETIRO PARCIAL IMSS | K15: Titular/Trabajador | L15: VAHV720130HCLLRC08 | M15: MONCLOVA | N15: 20201016 13:24:39 | T15: 1 | U15: 59877401249119 | W15: 202010161317410039 | Y15: 2606.4 | Z15: =IF(Y15=F15,"OK","Error 1") -> OK | AA15: Pago único | AC15: =IF(AA15="Pago 1",AB15+Y15,"0") -> 0 | AD15: 44056 | AE15: =IF(V15="SUBSECUENTE","No aplica",VLOOKUP(YEAR(AD15),'SALARIO MINIMO'!A1:B100,2,FALSE)) -> 123.22 | AF15: =IF(V15="SUBSECUENTE","No aplica",IF(YEAR(AD15)=2016,VLOOKUP(YEAR(AD15),UMA!A1:B100,2,FALSE),IF(MONTH(AD15)=1,VLOOKUP((YEAR(AD15))-1,UMA!A1:B100,2,FALSE),VLOOKUP(YEAR(AD15),UMA!A1:B100,2,FALSE)))) -> 86.88 | AG15: =IF(V15="SUBSECUENTE","No aplica",IFERROR(IF(SEARCH("desempleo",C15),AE15*30*10),AE15*30)) -> 3696.6 | AH15: =IF(V15="SUBSECUENTE","No aplica",IFERROR(IF(SEARCH("desempleo",C15),AF15*30*10),AF15*30)) -> 2606.4 | AI15: =IF(V15="SUBSECUENTE","No aplica",IF(AA15="Pago único",IF(AG15=Y15,"OK_SM",IF(AH15=Y15,"OK_UMA","Error Validacion 1")),IF(AG15=AC15,"OK_SM",IF(AH15=AC15,"OK_UMA","Error Validacion 1")))) -> OK_UMA | AJ15: =N15 -> 20201016 13:24:39 | AK15: 2606.4 | AL15: 0 | AM15: =IF(C15="RETIRO POR MATRIMONIO IMSS", 0,AK15*30) -> 78192 | AN15: =IF(C15="RETIRO POR MATRIMONIO IMSS", 0,AL15*90) -> 0 | AO15: =IF(V15="SUBSECUENTE","No aplica",IF(AA15="Pago único",IF(AM15=Y15,"OK_SALA",IF(AN15=Y15,"OK_SALB","Revisar_11.5%")),IF(AM15=AC15,"OK_SALA",IF(AN15=AC15,"OK_SALB","Revisar_11.5%")))) -> Revisar_11.5% | AP15: 71577.688 | AQ15: PROF-70 | AR15: 10.849608 | AS15: =AP15*AR15 -> 776589.86 | AT15: =IF(V15="SUBSECUENTE","No aplica",IF(AO15="OK_SALA","SAL_A",IF(AO15="OK_SALB","SAL_B",IF(AO15="Revisar_11.5%",AS15*0.115,"Error Validación 2")))) -> 89307.834 | AU15: =IF(V15="SUBSECUENTE","No aplica",IF(AA15="Pago único",IF(AT15<>"SAL_A",IF(ABS(AT15-Y15)<0.02,"OK_11.5%",IF(ABS(AS15-Y15)<0.02,"OK_RCV","Error Validación 4")),"SAL_A"),IF(AT15<>"SAL_A",IF(ABS(AT15-AC15)<0.02,"OK_11.5%",IF(ABS(AS15-AC15)<0.02,"OK_RCV","Error Validación 4")),"SAL_A"))) -> Error Validación 4 | AW15: =IF(V15="SUBSECUENTE",IF(AV15=Y15,"OK_IC","Revisar Pendientes"),"") | AY15: =IF(V15="SUBSECUENTES","No aplica",IF(AX15=Y15,"OK_SUMA","Diferencia pagos en curso")) -> Diferencia pagos en curso | AZ15: =IF(AA15="Pago 1",IF(AI15="OK_SM",AG15,IF(AI15="OK_UMA",AH15,IF(AO15="OK_SALA",AM15,IF(AO15="OK_SALB",AN15,IF(AU15="OK_11.5%",AT15,IF(AU15="OK_RCV",AS15,"Error en validación")))))),"No aplica") -> No aplica | BA15: =IF(ISNUMBER(AZ15),"OK_cálculo pago 1",AZ15) -> No aplica | BB15: =IF(AW15="OK_IC",AV15,IF(AY15="OK_SUMA",AX15,IF(AI15="OK_SM",AG15,IF(AI15="OK_UMA",AH15,IF(AO15="OK_SALA",AM15,IF(AO15="OK_SALB",AN15,IF(AU15="OK_11.5%",AT15,IF(AU15="OK_RCV",AS15,"Error en validación")))))))) -> 2606.4 | BC15: =IF(Z15="Error 1","No cuadran el Instructivo de Cobro y el monto de Cognos",IF(AND(AW15="Revisar Pendientes",AY15<>"OK_SUMA"),"Diferencia entre instructivo de cobro actual y de primer pago",IF(AI15<>"Error Validacion 1","Validación correcta",IF(OR(AO15="OK_SALA",AO15="OK_SALB"),"Validación correcta", IF(AU15="Error Validación 4", IF(AA15="Pago único","No cuadra el cálculo realizado contra Instructivo y Cognos","No cuadra cálculo realizado contra Instructivo"), "Validación correcta"))))) -> Validación correcta | BD15: =IF(BC15="Validación correcta","Ningún comentario",IF(BC15="No cuadran el Instructivo de Cobro y el monto de Cognos","Inconsistencia en los datos de origen","Inconsistencia entre datos de origen y cálculo")) -> Ningún comentario | BE15: Actual | BF15: Procesado
A16: 8000251457 | B16: 3300354654 | C16: RETIRO DE AYUDA PARA GASTOS DE MATRIMONIO IMSS | D16: CON IMAGENES COMPLETAS | E16: 44120.578 | F16: 2606.4 | G16: 0 | H16: 30119210265 | I16: HESL921127HDFRNS03 | J16: RETIRO PARCIAL IMSS | K16: Titular/Trabajador | L16: HESL921127HDFRNS03 | M16: MIXCOAC | N16: 20201016 13:44:50 | T16: 1 | U16: 75645953557216 | W16: 202010161341190042 | Y16: 2606.4 | Z16: =IF(Y16=F16,"OK","Error 1") -> OK | AA16: Pago único | AC16: =IF(AA16="Pago 1",AB16+Y16,"0") -> 0 | AD16: 44103 | AE16: =IF(V16="SUBSECUENTE","No aplica",VLOOKUP(YEAR(AD16),'SALARIO MINIMO'!A1:B100,2,FALSE)) -> 123.22 | AF16: =IF(V16="SUBSECUENTE","No aplica",IF(YEAR(AD16)=2016,VLOOKUP(YEAR(AD16),UMA!A1:B100,2,FALSE),IF(MONTH(AD16)=1,VLOOKUP((YEAR(AD16))-1,UMA!A1:B100,2,FALSE),VLOOKUP(YEAR(AD16),UMA!A1:B100,2,FALSE)))) -> 86.88 | AG16: =IF(V16="SUBSECUENTE","No aplica",IFERROR(IF(SEARCH("desempleo",C16),AE16*30*10),AE16*30)) -> 3696.6 | AH16: =IF(V16="SUBSECUENTE","No aplica",IFERROR(IF(SEARCH("desempleo",C16),AF16*30*10),AF16*30)) -> 2606.4 | AI16: =IF(V16="SUBSECUENTE","No aplica",IF(AA16="Pago único",IF(AG16=Y16,"OK_SM",IF(AH16=Y16,"OK_UMA","Error Validacion 1")),IF(AG16=AC16,"OK_SM",IF(AH16=AC16,"OK_UMA","Error Validacion 1")))) -> OK_UMA | AJ16: =N16 -> 20201016 13:44:50 | AK16: 2606.4 | AL16: 0 | AM16: =IF(C16="RETIRO POR MATRIMONIO IMSS", 0,AK16*30) -> 78192 | AN16: =IF(C16="RETIRO POR MATRIMONIO IMSS", 0,AL16*90) -> 0 | AO16: =IF(V16="SUBSECUENTE","No aplica",IF(AA16="Pago único",IF(AM16=Y16,"OK_SALA",IF(AN16=Y16,"OK_SALB","Revisar_11.5%")),IF(AM16=AC16,"OK_SALA",IF(AN16=AC16,"OK_SALB","Revisar_11.5%")))) -> Revisar_11.5% | AP16: 4575.5156 | AQ16: PROF-90 | AR16: 13.148607 | AS16: =AP16*AR16 -> 60161.656 | AT16: =IF(V16="SUBSECUENTE","No aplica",IF(AO16="OK_SALA","SAL_A",IF(AO16="OK_SALB","SAL_B",IF(AO16="Revisar_11.5%",AS16*0.115,"Error Validación 2")))) -> 6918.5905 | AU16: =IF(V16="SUBSECUENTE","No aplica",IF(AA16="Pago único",IF(AT16<>"SAL_A",IF(ABS(AT16-Y16)<0.02,"OK_11.5%",IF(ABS(AS16-Y16)<0.02,"OK_RCV","Error Validación 4")),"SAL_A"),IF(AT16<>"SAL_A",IF(ABS(AT16-AC16)<0.02,"OK_11.5%",IF(ABS(AS16-AC16)<0.02,"OK_RCV","Error Validación 4")),"SAL_A"))) -> Error Validación 4 | AW16: =IF(V16="SUBSECUENTE",IF(AV16=Y16,"OK_IC","Revisar Pendientes"),"") | AY16: =IF(V16="SUBSECUENTES","No aplica",IF(AX16=Y16,"OK_SUMA","Diferencia pagos en curso")) -> Diferencia pagos en curso | AZ16: =IF(AA16="Pago 1",IF(AI16="OK_SM",AG16,IF(AI16="OK_UMA",AH16,IF(AO16="OK_SALA",AM16,IF(AO16="OK_SALB",AN16,IF(AU16="OK_11.5%",AT16,IF(AU16="OK_RCV",AS16,"Error en validación")))))),"No aplica") -> No aplica | BA16: =IF(ISNUMBER(AZ16),"OK_cálculo pago 1",AZ16) -> No aplica | BB16: =IF(AW16="OK_IC",AV16,IF(AY16="OK_SUMA",AX16,IF(AI16="OK_SM",AG16,IF(AI16="OK_UMA",AH16,IF(AO16="OK_SALA",AM16,IF(AO16="OK_SALB",AN16,IF(AU16="OK_11.5%",AT16,IF(AU16="OK_RCV",AS16,"Error en validación")))))))) -> 2606.4 | BC16: =IF(Z16="Error 1","No cuadran el Instructivo de Cobro y el monto de Cognos",IF(AND(AW16="Revisar Pendientes",AY16<>"OK_SUMA"),"Diferencia entre instructivo de cobro actual y de primer pago",IF(AI16<>"Error Validacion 1","Validación correcta",IF(OR(AO16="OK_SALA",AO16="OK_SALB"),"Validación correcta", IF(AU16="Error Validación 4", IF(AA16="Pago único","No cuadra el cálculo realizado contra Instructivo y Cognos","No cuadra cálculo realizado contra Instructivo"), "Validación correcta"))))) -> Validación correcta | BD16: =IF(BC16="Validación correcta","Ningún comentario",IF(BC16="No cuadran el Instructivo de Cobro y el monto de Cognos","Inconsistencia en los datos de origen","Inconsistencia entre datos de origen y cálculo")) -> Ningún comentario | BE16: Actual | BF16: Procesado
A17: 8000250682 | B17: 3200650357 | C17: RETIRO POR DESEMPLEO IMSS | D17: CON IMAGENES COMPLETAS | E17: 44120.359 | F17: 15236.7 | G17: 0 | H17: 65078821405 | I17: MUGF880124HVZXNR01 | J17: RETIRO PARCIAL IMSS | K17: Titular/Trabajador | L17: MUGF880124HVZXNR01 | M17: VERACRUZ | N17: 20201016 08:28:58 | T17: 1 | U17: 82616750212668 | W17: 202010160823540123 | Y17: 15236.7 | Z17: =IF(Y17=F17,"OK","Error 1") -> OK | AA17: Pago único | AC17: =IF(AA17="Pago 1",AB17+Y17,"0") -> 0 | AD17: 44120 | AE17: =IF(V17="SUBSECUENTE","No aplica",VLOOKUP(YEAR(AD17),'SALARIO MINIMO'!A1:B100,2,FALSE)) -> 123.22 | AF17: =IF(V17="SUBSECUENTE","No aplica",IF(YEAR(AD17)=2016,VLOOKUP(YEAR(AD17),UMA!A1:B100,2,FALSE),IF(MONTH(AD17)=1,VLOOKUP((YEAR(AD17))-1,UMA!A1:B100,2,FALSE),VLOOKUP(YEAR(AD17),UMA!A1:B100,2,FALSE)))) -> 86.88 | AG17: =IF(V17="SUBSECUENTE","No aplica",IFERROR(IF(SEARCH("desempleo",C17),AE17*30*10),AE17*30)) -> 36966 | AH17: =IF(V17="SUBSECUENTE","No aplica",IFERROR(IF(SEARCH("desempleo",C17),AF17*30*10),AF17*30)) -> 26064 | AI17: =IF(V17="SUBSECUENTE","No aplica",IF(AA17="Pago único",IF(AG17=Y17,"OK_SM",IF(AH17=Y17,"OK_UMA","Error Validacion 1")),IF(AG17=AC17,"OK_SM",IF(AH17=AC17,"OK_UMA","Error Validacion 1")))) -> Error Validacion 1 | AJ17: =N17 -> 20201016 08:28:58 | AK17: 507.89 | AL17: 542.49 | AM17: =IF(C17="RETIRO POR MATRIMONIO IMSS", 0,AK17*30) -> 15236.7 | AN17: =IF(C17="RETIRO POR MATRIMONIO IMSS", 0,AL17*90) -> 48824.1 | AO17: =IF(V17="SUBSECUENTE","No aplica",IF(AA17="Pago único",IF(AM17=Y17,"OK_SALA",IF(AN17=Y17,"OK_SALB","Revisar_11.5%")),IF(AM17=AC17,"OK_SALA",IF(AN17=AC17,"OK_SALB","Revisar_11.5%")))) -> OK_SALA | AP17: 9937.8417 | AQ17: PROF-85 | AR17: 13.238638 | AS17: =AP17*AR17 -> 131563.49 | AT17: =IF(V17="SUBSECUENTE","No aplica",IF(AO17="OK_SALA","SAL_A",IF(AO17="OK_SALB","SAL_B",IF(AO17="Revisar_11.5%",AS17*0.115,"Error Validación 2")))) -> SAL_A | AU17: =IF(V17="SUBSECUENTE","No aplica",IF(AA17="Pago único",IF(AT17<>"SAL_A",IF(ABS(AT17-Y17)<0.02,"OK_11.5%",IF(ABS(AS17-Y17)<0.02,"OK_RCV","Error Validación 4")),"SAL_A"),IF(AT17<>"SAL_A",IF(ABS(AT17-AC17)<0.02,"OK_11.5%",IF(ABS(AS17-AC17)<0.02,"OK_RCV","Error Validación 4")),"SAL_A"))) -> SAL_A | AW17: =IF(V17="SUBSECUENTE",IF(AV17=Y17,"OK_IC","Revisar Pendientes"),"") | AY17: =IF(V17="SUBSECUENTES","No aplica",IF(AX17=Y17,"OK_SUMA","Diferencia pagos en curso")) -> Diferencia pagos en curso | AZ17: =IF(AA17="Pago 1",IF(AI17="OK_SM",AG17,IF(AI17="OK_UMA",AH17,IF(AO17="OK_SALA",AM17,IF(AO17="OK_SALB",AN17,IF(AU17="OK_11.5%",AT17,IF(AU17="OK_RCV",AS17,"Error en validación")))))),"No aplica") -> No aplica | BA17: =IF(ISNUMBER(AZ17),"OK_cálculo pago 1",AZ17) -> No aplica | BB17: =IF(AW17="OK_IC",AV17,IF(AY17="OK_SUMA",AX17,IF(AI17="OK_SM",AG17,IF(AI17="OK_UMA",AH17,IF(AO17="OK_SALA",AM17,IF(AO17="OK_SALB",AN17,IF(AU17="OK_11.5%",AT17,IF(AU17="OK_RCV",AS17,"Error en validación")))))))) -> 15236.7 | BC17: =IF(Z17="Error 1","No cuadran el Instructivo de Cobro y el monto de Cognos",IF(AND(AW17="Revisar Pendientes",AY17<>"OK_SUMA"),"Diferencia entre instructivo de cobro actual y de primer pago",IF(AI17<>"Error Validacion 1","Validación correcta",IF(OR(AO17="OK_SALA",AO17="OK_SALB"),"Validación correcta", IF(AU17="Error Validación 4", IF(AA17="Pago único","No cuadra el cálculo realizado contra Instructivo y Cognos","No cuadra cálculo realizado contra Instructivo"), "Validación correcta"))))) -> Validación correcta | BD17: =IF(BC17="Validación correcta","Ningún comentario",IF(BC17="No cuadran el Instructivo de Cobro y el monto de Cognos","Inconsistencia en los datos de origen","Inconsistencia entre datos de origen y cálculo")) -> Ningún comentario | BE17: Actual | BF17: Procesado
